Workbook

Sheet ACTION Element Code Table
A1: Combined code | B1: Type (B-Builder, E-Electrical) | C1: Description | D1: Element_CodePSB_Element1(PSB_Element1) | E1: Element | F1: Subelement_CodePSB_Sub-element1(PSB_Sub-element1) | G1: Subelement | H1: Component_Code(PSB_Component1) | I1: Component | J1: Attribute_Code(PSB_Attribute1) | K1: Attribute
A2: =D2&"_"&F2&"_"&H2&"_"&J2 -> AC_NULL_NULL_NULL | B2: E | C2: AIR-CONDITIONING | D2: AC | E2: AIR-CONDITIONING | F2: NULL | H2: NULL | J2: NULL
A3: =D3&"_"&F3&"_"&H3&"_"&J3 -> AC_AC02_NULL_NULL | B3: E | C3: A/C main plant equipment | D3: AC | E3: AIR-CONDITIONING | F3: AC02 | G3: A/C main plant equipment | H3: NULL | J3: NULL
A4: =D4&"_"&F4&"_"&H4&"_"&J4 -> AC_AC02_AC0025_NULL | B4: E | C4: Air-cooled chiller | D4: AC | E4: AIR-CONDITIONING | F4: AC02 | G4: A/C main plant equipment | H4: AC0025 | I4: Air-cooled chiller | J4: NULL
A5: =D5&"_"&F5&"_"&H5&"_"&J5 -> AC_AC02_AC0035_NULL | B5: E | C5: Chiller | D5: AC | E5: AIR-CONDITIONING | F5: AC02 | G5: A/C main plant equipment | H5: AC0035 | I5: Chiller | J5: NULL
A6: =D6&"_"&F6&"_"&H6&"_"&J6 -> AC_AC02_AC0030_NULL | B6: E | C6: Compressor | D6: AC | E6: AIR-CONDITIONING | F6: AC02 | G6: A/C main plant equipment | H6: AC0030 | I6: Compressor | J6: NULL
A7: =D7&"_"&F7&"_"&H7&"_"&J7 -> AC_AC02_AC0040_NULL | B7: E | C7: Condenser | D7: AC | E7: AIR-CONDITIONING | F7: AC02 | G7: A/C main plant equipment | H7: AC0040 | I7: Condenser | J7: NULL
A8: =D8&"_"&F8&"_"&H8&"_"&J8 -> AC_AC02_AC0020_NULL | B8: E | C8: Fresh water cooled chiller | D8: AC | E8: AIR-CONDITIONING | F8: AC02 | G8: A/C main plant equipment | H8: AC0020 | I8: Fresh water cooled chiller | J8: NULL
A9: =D9&"_"&F9&"_"&H9&"_"&J9 -> AC_AC02_AC0015_NULL | B9: E | C9: Seawater cooled chiller | D9: AC | E9: AIR-CONDITIONING | F9: AC02 | G9: A/C main plant equipment | H9: AC0015 | I9: Seawater cooled chiller | J9: NULL
A10: =D10&"_"&F10&"_"&H10&"_"&J10 -> AC_AC03_NULL_NULL | B10: E | C10: Air distribution equipment | D10: AC | E10: AIR-CONDITIONING | F10: AC03 | G10: Air distribution equipment | H10: NULL | J10: NULL
A11: =D11&"_"&F11&"_"&H11&"_"&J11 -> AC_AC03_AC0045_NULL | B11: E | C11: Chilled water AHU | D11: AC | E11: AIR-CONDITIONING | F11: AC03 | G11: Air distribution equipment | H11: AC0045 | I11: Chilled water AHU | J11: NULL
A12: =D12&"_"&F12&"_"&H12&"_"&J12 -> AC_AC03_AC0050_NULL | B12: E | C12: Chilled water FCU | D12: AC | E12: AIR-CONDITIONING | F12: AC03 | G12: Air distribution equipment | H12: AC0050 | I12: Chilled water FCU | J12: NULL
A13: =D13&"_"&F13&"_"&H13&"_"&J13 -> AC_AC03_AC0055_NULL | B13: E | C13: DX AHU | D13: AC | E13: AIR-CONDITIONING | F13: AC03 | G13: Air distribution equipment | H13: AC0055 | I13: DX AHU | J13: NULL
A14: =D14&"_"&F14&"_"&H14&"_"&J14 -> AC_AC03_AC0060_NULL | B14: E | C14: DX FCU | D14: AC | E14: AIR-CONDITIONING | F14: AC03 | G14: Air distribution equipment | H14: AC0060 | I14: DX FCU | J14: NULL
A15: =D15&"_"&F15&"_"&H15&"_"&J15 -> AC_AC03_AC0070_NULL | B15: E | C15: Fire damper | D15: AC | E15: AIR-CONDITIONING | F15: AC03 | G15: Air distribution equipment | H15: AC0070 | I15: Fire damper | J15: NULL
A16: =D16&"_"&F16&"_"&H16&"_"&J16 -> AC_AC03_AC0065_NULL | B16: E | C16: Split A/C unit | D16: AC | E16: AIR-CONDITIONING | F16: AC03 | G16: Air distribution equipment | H16: AC0065 | I16: Split A/C unit | J16: NULL
A17: =D17&"_"&F17&"_"&H17&"_"&J17 -> AC_AC09_NULL_NULL | B17: E | C17: Cold stores | D17: AC | E17: AIR-CONDITIONING | F17: AC09 | G17: Cold stores | H17: NULL | J17: NULL
A18: =D18&"_"&F18&"_"&H18&"_"&J18 -> AC_AC08_NULL_NULL | B18: E | C18: Fan | D18: AC | E18: AIR-CONDITIONING | F18: AC08 | G18: Fan | H18: NULL | J18: NULL
A19: =D19&"_"&F19&"_"&H19&"_"&J19 -> AC_AC08_AC0120_NULL | B19: E | C19: Axial fan | D19: AC | E19: AIR-CONDITIONING | F19: AC08 | G19: Fan | H19: AC0120 | I19: Axial fan | J19: NULL
A20: =D20&"_"&F20&"_"&H20&"_"&J20 -> AC_AC08_AC0125_NULL | B20: E | C20: Centrifugal fan | D20: AC | E20: AIR-CONDITIONING | F20: AC08 | G20: Fan | H20: AC0125 | I20: Centrifugal fan | J20: NULL
A21: =D21&"_"&F21&"_"&H21&"_"&J21 -> AC_AC07_NULL_NULL | B21: E | C21: Others | D21: AC | E21: AIR-CONDITIONING | F21: AC07 | G21: Others | H21: NULL | J21: NULL
A22: =D22&"_"&F22&"_"&H22&"_"&J22 -> AC_AC07_AC0115_NULL | B22: E | C22: Calorifier | D22: AC | E22: AIR-CONDITIONING | F22: AC07 | G22: Others | H22: AC0115 | I22: Calorifier | J22: NULL
A23: =D23&"_"&F23&"_"&H23&"_"&J23 -> AC_AC07_AC0110_NULL | B23: E | C23: Water pump | D23: AC | E23: AIR-CONDITIONING | F23: AC07 | G23: Others | H23: AC0110 | I23: Water pump | J23: NULL
A24: =D24&"_"&F24&"_"&H24&"_"&J24 -> AC_AC10_NULL_NULL | B24: E | C24: Others | D24: AC | E24: AIR-CONDITIONING | F24: AC10 | G24: Others | H24: NULL | J24: NULL
A25: =D25&"_"&F25&"_"&H25&"_"&J25 -> AC_AC05_NULL_NULL | B25: E | C25: Sea water cooling equipment | D25: AC | E25: AIR-CONDITIONING | F25: AC05 | G25: Sea water cooling equipment | H25: NULL | J25: NULL
A26: =D26&"_"&F26&"_"&H26&"_"&J26 -> AC_AC05_AC0095_NULL | B26: E | C26: Heat exchanger | D26: AC | E26: AIR-CONDITIONING | F26: AC05 | G26: Sea water cooling equipment | H26: AC0095 | I26: Heat exchanger | J26: NULL
A27: =D27&"_"&F27&"_"&H27&"_"&J27 -> AC_AC05_AC0090_NULL | B27: E | C27: Sea water screen | D27: AC | E27: AIR-CONDITIONING | F27: AC05 | G27: Sea water cooling equipment | H27: AC0090 | I27: Sea water screen | J27: NULL
A28: =D28&"_"&F28&"_"&H28&"_"&J28 -> AC_AC05_AC0085_NULL | B28: E | C28: Sea water strainer | D28: AC | E28: AIR-CONDITIONING | F28: AC05 | G28: Sea water cooling equipment | H28: AC0085 | I28: Sea water strainer | J28: NULL
A29: =D29&"_"&F29&"_"&H29&"_"&J29 -> AC_AC05_AC0100_NULL | B29: E | C29: Seawater pump | D29: AC | E29: AIR-CONDITIONING | F29: AC05 | G29: Sea water cooling equipment | H29: AC0100 | I29: Seawater pump | J29: NULL
A30: =D30&"_"&F30&"_"&H30&"_"&J30 -> AC_AC01_NULL_NULL | B30: E | C30: System general | D30: AC | E30: AIR-CONDITIONING | F30: AC01 | G30: System general | H30: NULL | J30: NULL
A31: =D31&"_"&F31&"_"&H31&"_"&J31 -> AC_AC01_AC0010_NULL | B31: E | C31: Motor load | D31: AC | E31: AIR-CONDITIONING | F31: AC01 | G31: System general | H31: AC0010 | I31: Motor load | J31: NULL
A32: =D32&"_"&F32&"_"&H32&"_"&J32 -> AC_AC01_AC0005_NULL | B32: E | C32: Total cooling load (Kw) | D32: AC | E32: AIR-CONDITIONING | F32: AC01 | G32: System general | H32: AC0005 | I32: Total cooling load (Kw) | J32: NULL
A33: =D33&"_"&F33&"_"&H33&"_"&J33 -> AC_AC04_NULL_NULL | B33: E | C33: Water cooling equipment | D33: AC | E33: AIR-CONDITIONING | F33: AC04 | G33: Water cooling equipment | H33: NULL | J33: NULL
A34: =D34&"_"&F34&"_"&H34&"_"&J34 -> AC_AC04_AC0080_NULL | B34: E | C34: Condensing water pump | D34: AC | E34: AIR-CONDITIONING | F34: AC04 | G34: Water cooling equipment | H34: AC0080 | I34: Condensing water pump | J34: NULL
A35: =D35&"_"&F35&"_"&H35&"_"&J35 -> AC_AC04_AC0075_NULL | B35: E | C35: Cooling tower | D35: AC | E35: AIR-CONDITIONING | F35: AC04 | G35: Water cooling equipment | H35: AC0075 | I35: Cooling tower | J35: NULL
A36: =D36&"_"&F36&"_"&H36&"_"&J36 -> AC_AC06_NULL_NULL | B36: E | C36: Water treatment | D36: AC | E36: AIR-CONDITIONING | F36: AC06 | G36: Water treatment | H36: NULL | J36: NULL
A37: =D37&"_"&F37&"_"&H37&"_"&J37 -> AC_AC06_AC0105_NULL | B37: E | C37: Chlorinator | D37: AC | E37: AIR-CONDITIONING | F37: AC06 | G37: Water treatment | H37: AC0105 | I37: Chlorinator | J37: NULL
A38: =D38&"_"&F38&"_"&H38&"_"&J38 -> AC_AC11_NULL_NULL | B38: E | C38: Unitary Air Conditioners | D38: AC | E38: AIR-CONDITIONING | F38: AC11 | G38: Unitary Air Conditioners | H38: NULL | J38: NULL
A39: =D39&"_"&F39&"_"&H39&"_"&J39 -> AC_AC11_AC001_NULL | B39: E | C39: Internally mounted Air to Air Packaged Air Conditione | D39: AC | E39: AIR-CONDITIONING | F39: AC11 | G39: Unitary Air Conditioners | H39: AC001 | I39: Internally mounted Air to Air Packaged Air Conditione | J39: NULL
A40: =D40&"_"&F40&"_"&H40&"_"&J40 -> AC_AC11_AC001_AC0001 | B40: E | C40: Cooling capacity : 10.1 up to 15 kw | D40: AC | E40: AIR-CONDITIONING | F40: AC11 | G40: Unitary Air Conditioners | H40: AC001 | I40: Internally mounted Air to Air Packaged Air Conditione | J40: AC0001 | K40: Cooling capacity : 10.1 up to 15 kw
...

Sheet AR
A1: UniqueID | B1: Category | C1: Family Name | D1: Element_CodePSB_Element1 | E1: PSB_Floor | F1: Subelement_CodePSB_Sub-element1 | G1: PSB_Element1 | H1: PSB_Sub-element1 | I1: PSB_Component1 | J1: PSB_Attribute1 | K1: PSB_element_doc1 | L1: PSB_manufacturer1 | M1: PSB_Remarks1 | N1: PSB_Element2 | O1: PSB_Sub-element2 | P1: PSB_Component2 | Q1: PSB_Attribute2 | R1: PSB_element_doc2 | S1: PSB_manufacturer2 | T1: PSB_Remarks2 | U1: PSB_Element3 | V1: PSB_Sub-element3 | W1: PSB_Component3 | X1: PSB_Attribute3 | Y1: PSB_element_doc3 | Z1: PSB_manufacturer3 | AA1: PSB_Remarks3 | AB1: PSB_Element4 | AC1: PSB_Sub-element4 | AD1: PSB_Component4 | AE1: PSB_Attribute4 | AF1: PSB_element_doc4 | AG1: PSB_manufacturer4 | AH1: PSB_Remarks4 | AI1: PSB_Element5 | AJ1: PSB_Sub-element5 | AK1: PSB_Component5 | AL1: PSB_Attribute5 | AM1: PSB_element_doc5 | AN1: PSB_manufacturer5 | AO1: PSB_Remarks5 | AP1: PSB_MWORRF_link | AQ1: PSB_MWO_link | AR1: PSB_WO_link | AS1: SoR_no | AT1: PSB_Ins_Sch_Des | AU1: psb_CDELevel | AV1: PSB_feature | AW1: PSB_Ins_Interval | AX1: ArchSD Checking on Element 1 | AY1: ArchSD Checking on Element 2 | AZ1: ArchSD Checking on Element 3 | BA1: ArchSD Checking on Element 4 | BB1: ArchSD Checking on Element 5 | BC1: BIM Element Code 1 (Location Code+Floor+Element+Element No) | BD1: BIM Element Code 2 (Location Code+Floor+Element+Element No) | BE1: BIM Element Code 3 (Location Code+Floor+Element+Element No) | BF1: BIM Element Code 4 (Location Code+Floor+Element+Element No)3 | BG1: BIM Element Code 5 (Location Code+Floor+Element+Element No)3 | BH1: Element ID for Element1 is repeated? | BI1: Element ID for Element2 is repeated? | BJ1: Element ID for Element3 is repeated? | BK1: Element ID for Element4 is repeated? | BL1: Element ID for Element5 is repeated? | BM1: Comment by ArchSD | BN1: Type (For Reference) | BO1: Family (For Reference) | BP1: Category (For Reference)
G2: STR | H2: SHAF | I2: PANAC | J2: NULL | K2: NULL | L2: NULL | M2: NULL | N2: NULL | O2: NULL | P2: NULL | Q2: NULL | R2: NULL | S2: NULL | T2: NULL | U2: NULL | V2: NULL | W2: NULL | X2: NULL | Y2: NULL | Z2: NULL | AA2: NULL | AB2: NULL | AC2: NULL | AD2: NULL | AE2: NULL | AF2: NULL | AG2: NULL | AH2: NULL | AI2: NULL | AJ2: NULL | AK2: NULL | AL2: NULL | AM2: NULL | AN2: NULL | AO2: NULL | AP2: NULL | AQ2: NULL | AR2: NULL | AS2: NULL | AT2: NULL | AU2: NULL | AV2: NULL | AW2: NULL | AX2: =IF(COUNTIF('ACTION Element Code Table'!$A:$A,G2&"_"&H2&"_"&I2&"_"&J2)=1,VLOOKUP(G2&"_"&H2&"_"&I2&"_"&J2,'ACTION Element Code Table'!$A:$C,3,FALSE),IF(G2&"_"&H2&"_"&I2&"_"&J2="NULL_NULL_NULL_NULL","NULL","Not exist in ACTION Element Code Table")) -> ACCESS PANEL OF SHAFT | AY2: =IF(COUNTIF('ACTION Element Code Table'!$A:$A,N2&"_"&O2&"_"&P2&"_"&Q2)=1,VLOOKUP(N2&"_"&O2&"_"&P2&"_"&Q2,'ACTION Element Code Table'!$A:$C,3,FALSE),IF(N2&"_"&O2&"_"&P2&"_"&Q2="NULL_NULL_NULL_NULL","NULL","Not exist in ACTION Element Code Table")) -> NULL | AZ2: =IF(COUNTIF('ACTION Element Code Table'!$A:$A,U2&"_"&V2&"_"&W2&"_"&X2)=1,VLOOKUP(U2&"_"&V2&"_"&W2&"_"&X2,'ACTION Element Code Table'!$A:$C,3,FALSE),IF(U2&"_"&V2&"_"&W2&"_"&X2="NULL_NULL_NULL_NULL","NULL","Not exist in ACTION Element Code Table")) -> NULL | BA2: =IF(COUNTIF('ACTION Element Code Table'!$A:$A,AB2&"_"&AC2&"_"&AD2&"_"&AE2)=1,VLOOKUP(AB2&"_"&AC2&"_"&AD2&"_"&AE2,'ACTION Element Code Table'!$A:$C,3,FALSE),IF(AB2&"_"&AC2&"_"&AD2&"_"&AE2="NULL_NULL_NULL_NULL","NULL","Not exist in ACTION Element Code Table")) -> NULL | BB2: =IF(COUNTIF('ACTION Element Code Table'!$A:$A,AI2&"_"&AJ2&"_"&AK2&"_"&AL2)=1,VLOOKUP(AI2&"_"&AJ2&"_"&AK2&"_"&AL2,'ACTION Element Code Table'!$A:$C,3,FALSE),IF(AI2&"_"&AJ2&"_"&AK2&"_"&AL2="NULL_NULL_NULL_NULL","NULL","Not exist in ACTION Element Code Table")) -> NULL | BC2: =D2&E2&G2&H2&I2&J2&F2 -> STRSHAFPANACNULL | BD2: =D2&E2&N2&O2&P2&Q2&F2 -> NULLNULLNULLNULL | BE2: =D2&E2&U2&V2&W2&X2&F2 -> NULLNULLNULLNULL | BF2: =D2&E2&AB2&AC2&AD2&AE2&F2 -> NULLNULLNULLNULL | BG2: =D2&E2&AI2&AJ2&AK2&AL2&F2 -> NULLNULLNULLNULL | BH2: =IF(COUNTIF($BB:$BF,BC2)>1,"Duplicated","") | BI2: =IF(COUNTIF($BB:$BF,BD2)>1,"Duplicated","") -> Duplicated | BJ2: =IF(COUNTIF($BB:$BF,BE2)>1,"Duplicated","") -> Duplicated | BK2: =IF(COUNTIF($BB:$BF,BF2)>1,"Duplicated","") -> Duplicated | BL2: =IF(COUNTIF($BB:$BF,BG2)>1,"Duplicated","") -> Duplicated | BM2: Access Panel
G3: STR | H3: BAL | I3: BALU | J3: NULL | K3: NULL | L3: NULL | M3: NULL | N3: NULL | O3: NULL | P3: NULL | Q3: NULL | R3: NULL | S3: NULL | T3: NULL | U3: NULL | V3: NULL | W3: NULL | X3: NULL | Y3: NULL | Z3: NULL | AA3: NULL | AB3: NULL | AC3: NULL | AD3: NULL | AE3: NULL | AF3: NULL | AG3: NULL | AH3: NULL | AI3: NULL | AJ3: NULL | AK3: NULL | AL3: NULL | AM3: NULL | AN3: NULL | AO3: NULL | AP3: NULL | AQ3: NULL | AR3: NULL | AS3: NULL | AT3: NULL | AU3: NULL | AV3: NULL | AW3: NULL | AX3: =IF(COUNTIF('ACTION Element Code Table'!$A:$A,G3&"_"&H3&"_"&I3&"_"&J3)=1,VLOOKUP(G3&"_"&H3&"_"&I3&"_"&J3,'ACTION Element Code Table'!$A:$C,3,FALSE),IF(G3&"_"&H3&"_"&I3&"_"&J3="NULL_NULL_NULL_NULL","NULL","Not exist in ACTION Element Code Table")) -> BALUSTRADE ON BALCONY | AY3: =IF(COUNTIF('ACTION Element Code Table'!$A:$A,N3&"_"&O3&"_"&P3&"_"&Q3)=1,VLOOKUP(N3&"_"&O3&"_"&P3&"_"&Q3,'ACTION Element Code Table'!$A:$C,3,FALSE),IF(N3&"_"&O3&"_"&P3&"_"&Q3="NULL_NULL_NULL_NULL","NULL","Not exist in ACTION Element Code Table")) -> NULL | AZ3: =IF(COUNTIF('ACTION Element Code Table'!$A:$A,U3&"_"&V3&"_"&W3&"_"&X3)=1,VLOOKUP(U3&"_"&V3&"_"&W3&"_"&X3,'ACTION Element Code Table'!$A:$C,3,FALSE),IF(U3&"_"&V3&"_"&W3&"_"&X3="NULL_NULL_NULL_NULL","NULL","Not exist in ACTION Element Code Table")) -> NULL | BA3: =IF(COUNTIF('ACTION Element Code Table'!$A:$A,AB3&"_"&AC3&"_"&AD3&"_"&AE3)=1,VLOOKUP(AB3&"_"&AC3&"_"&AD3&"_"&AE3,'ACTION Element Code Table'!$A:$C,3,FALSE),IF(AB3&"_"&AC3&"_"&AD3&"_"&AE3="NULL_NULL_NULL_NULL","NULL","Not exist in ACTION Element Code Table")) -> NULL | BB3: =IF(COUNTIF('ACTION Element Code Table'!$A:$A,AI3&"_"&AJ3&"_"&AK3&"_"&AL3)=1,VLOOKUP(AI3&"_"&AJ3&"_"&AK3&"_"&AL3,'ACTION Element Code Table'!$A:$C,3,FALSE),IF(AI3&"_"&AJ3&"_"&AK3&"_"&AL3="NULL_NULL_NULL_NULL","NULL","Not exist in ACTION Element Code Table")) -> NULL | BC3: =D3&E3&G3&H3&I3&J3&F3 -> STRBALBALUNULL | BD3: =D3&E3&N3&O3&P3&Q3&F3 -> NULLNULLNULLNULL | BE3: =D3&E3&U3&V3&W3&X3&F3 -> NULLNULLNULLNULL | BF3: =D3&E3&AB3&AC3&AD3&AE3&F3 -> NULLNULLNULLNULL | BG3: =D3&E3&AI3&AJ3&AK3&AL3&F3 -> NULLNULLNULLNULL | BH3: =IF(COUNTIF($BB:$BF,BC3)>1,"Duplicated","") | BI3: =IF(COUNTIF($BB:$BF,BD3)>1,"Duplicated","") -> Duplicated | BJ3: =IF(COUNTIF($BB:$BF,BE3)>1,"Duplicated","") -> Duplicated | BK3: =IF(COUNTIF($BB:$BF,BF3)>1,"Duplicated","") -> Duplicated | BL3: =IF(COUNTIF($BB:$BF,BG3)>1,"Duplicated","") -> Duplicated | BM3: Balcony Railing | BN3: Railing
G4: STR | H4: BAL | I4: BALU | J4: BR | K4: NULL | L4: NULL | M4: NULL | N4: NULL | O4: NULL | P4: NULL | Q4: NULL | R4: NULL | S4: NULL | T4: NULL | U4: NULL | V4: NULL | W4: NULL | X4: NULL | Y4: NULL | Z4: NULL | AA4: NULL | AB4: NULL | AC4: NULL | AD4: NULL | AE4: NULL | AF4: NULL | AG4: NULL | AH4: NULL | AI4: NULL | AJ4: NULL | AK4: NULL | AL4: NULL | AM4: NULL | AN4: NULL | AO4: NULL | AP4: NULL | AQ4: NULL | AR4: NULL | AS4: NULL | AT4: NULL | AU4: NULL | AV4: NULL | AW4: NULL | AX4: =IF(COUNTIF('ACTION Element Code Table'!$A:$A,G4&"_"&H4&"_"&I4&"_"&J4)=1,VLOOKUP(G4&"_"&H4&"_"&I4&"_"&J4,'ACTION Element Code Table'!$A:$C,3,FALSE),IF(G4&"_"&H4&"_"&I4&"_"&J4="NULL_NULL_NULL_NULL","NULL","Not exist in ACTION Element Code Table")) -> BRICK BALUSTRADE ON BALCONY | AY4: =IF(COUNTIF('ACTION Element Code Table'!$A:$A,N4&"_"&O4&"_"&P4&"_"&Q4)=1,VLOOKUP(N4&"_"&O4&"_"&P4&"_"&Q4,'ACTION Element Code Table'!$A:$C,3,FALSE),IF(N4&"_"&O4&"_"&P4&"_"&Q4="NULL_NULL_NULL_NULL","NULL","Not exist in ACTION Element Code Table")) -> NULL | AZ4: =IF(COUNTIF('ACTION Element Code Table'!$A:$A,U4&"_"&V4&"_"&W4&"_"&X4)=1,VLOOKUP(U4&"_"&V4&"_"&W4&"_"&X4,'ACTION Element Code Table'!$A:$C,3,FALSE),IF(U4&"_"&V4&"_"&W4&"_"&X4="NULL_NULL_NULL_NULL","NULL","Not exist in ACTION Element Code Table")) -> NULL | BA4: =IF(COUNTIF('ACTION Element Code Table'!$A:$A,AB4&"_"&AC4&"_"&AD4&"_"&AE4)=1,VLOOKUP(AB4&"_"&AC4&"_"&AD4&"_"&AE4,'ACTION Element Code Table'!$A:$C,3,FALSE),IF(AB4&"_"&AC4&"_"&AD4&"_"&AE4="NULL_NULL_NULL_NULL","NULL","Not exist in ACTION Element Code Table")) -> NULL | BB4: =IF(COUNTIF('ACTION Element Code Table'!$A:$A,AI4&"_"&AJ4&"_"&AK4&"_"&AL4)=1,VLOOKUP(AI4&"_"&AJ4&"_"&AK4&"_"&AL4,'ACTION Element Code Table'!$A:$C,3,FALSE),IF(AI4&"_"&AJ4&"_"&AK4&"_"&AL4="NULL_NULL_NULL_NULL","NULL","Not exist in ACTION Element Code Table")) -> NULL | BC4: =D4&E4&G4&H4&I4&J4&F4 -> STRBALBALUBR | BD4: =D4&E4&N4&O4&P4&Q4&F4 -> NULLNULLNULLNULL | BE4: =D4&E4&U4&V4&W4&X4&F4 -> NULLNULLNULLNULL | BF4: =D4&E4&AB4&AC4&AD4&AE4&F4 -> NULLNULLNULLNULL | BG4: =D4&E4&AI4&AJ4&AK4&AL4&F4 -> NULLNULLNULLNULL | BH4: =IF(COUNTIF($BB:$BF,BC4)>1,"Duplicated","") | BI4: =IF(COUNTIF($BB:$BF,BD4)>1,"Duplicated","") -> Duplicated | BJ4: =IF(COUNTIF($BB:$BF,BE4)>1,"Duplicated","") -> Duplicated | BK4: =IF(COUNTIF($BB:$BF,BF4)>1,"Duplicated","") -> Duplicated | BL4: =IF(COUNTIF($BB:$BF,BG4)>1,"Duplicated","") -> Duplicated | BM4: Balustrade | BN4: Railing
G5: SPE | H5: SPORT | I5: STRBC | J5: NULL | K5: NULL | L5: NULL | M5: NULL | N5: NULL | O5: NULL | P5: NULL | Q5: NULL | R5: NULL | S5: NULL | T5: NULL | U5: NULL | V5: NULL | W5: NULL | X5: NULL | Y5: NULL | Z5: NULL | AA5: NULL | AB5: NULL | AC5: NULL | AD5: NULL | AE5: NULL | AF5: NULL | AG5: NULL | AH5: NULL | AI5: NULL | AJ5: NULL | AK5: NULL | AL5: NULL | AM5: NULL | AN5: NULL | AO5: NULL | AP5: NULL | AQ5: NULL | AR5: NULL | AS5: NULL | AT5: NULL | AU5: NULL | AV5: NULL | AW5: NULL | AX5: =IF(COUNTIF('ACTION Element Code Table'!$A:$A,G5&"_"&H5&"_"&I5&"_"&J5)=1,VLOOKUP(G5&"_"&H5&"_"&I5&"_"&J5,'ACTION Element Code Table'!$A:$C,3,FALSE),IF(G5&"_"&H5&"_"&I5&"_"&J5="NULL_NULL_NULL_NULL","NULL","Not exist in ACTION Element Code Table")) -> STRUCTURE OF BALL COURT | AY5: =IF(COUNTIF('ACTION Element Code Table'!$A:$A,N5&"_"&O5&"_"&P5&"_"&Q5)=1,VLOOKUP(N5&"_"&O5&"_"&P5&"_"&Q5,'ACTION Element Code Table'!$A:$C,3,FALSE),IF(N5&"_"&O5&"_"&P5&"_"&Q5="NULL_NULL_NULL_NULL","NULL","Not exist in ACTION Element Code Table")) -> NULL | AZ5: =IF(COUNTIF('ACTION Element Code Table'!$A:$A,U5&"_"&V5&"_"&W5&"_"&X5)=1,VLOOKUP(U5&"_"&V5&"_"&W5&"_"&X5,'ACTION Element Code Table'!$A:$C,3,FALSE),IF(U5&"_"&V5&"_"&W5&"_"&X5="NULL_NULL_NULL_NULL","NULL","Not exist in ACTION Element Code Table")) -> NULL | BA5: =IF(COUNTIF('ACTION Element Code Table'!$A:$A,AB5&"_"&AC5&"_"&AD5&"_"&AE5)=1,VLOOKUP(AB5&"_"&AC5&"_"&AD5&"_"&AE5,'ACTION Element Code Table'!$A:$C,3,FALSE),IF(AB5&"_"&AC5&"_"&AD5&"_"&AE5="NULL_NULL_NULL_NULL","NULL","Not exist in ACTION Element Code Table")) -> NULL | BB5: =IF(COUNTIF('ACTION Element Code Table'!$A:$A,AI5&"_"&AJ5&"_"&AK5&"_"&AL5)=1,VLOOKUP(AI5&"_"&AJ5&"_"&AK5&"_"&AL5,'ACTION Element Code Table'!$A:$C,3,FALSE),IF(AI5&"_"&AJ5&"_"&AK5&"_"&AL5="NULL_NULL_NULL_NULL","NULL","Not exist in ACTION Element Code Table")) -> NULL | BC5: =D5&E5&G5&H5&I5&J5&F5 -> SPESPORTSTRBCNULL | BD5: =D5&E5&N5&O5&P5&Q5&F5 -> NULLNULLNULLNULL | BE5: =D5&E5&U5&V5&W5&X5&F5 -> NULLNULLNULLNULL | BF5: =D5&E5&AB5&AC5&AD5&AE5&F5 -> NULLNULLNULLNULL | BG5: =D5&E5&AI5&AJ5&AK5&AL5&F5 -> NULLNULLNULLNULL | BH5: =IF(COUNTIF($BB:$BF,BC5)>1,"Duplicated","") | BI5: =IF(COUNTIF($BB:$BF,BD5)>1,"Duplicated","") -> Duplicated | BJ5: =IF(COUNTIF($BB:$BF,BE5)>1,"Duplicated","") -> Duplicated | BK5: =IF(COUNTIF($BB:$BF,BF5)>1,"Duplicated","") -> Duplicated | BL5: =IF(COUNTIF($BB:$BF,BG5)>1,"Duplicated","") -> Duplicated | BM5: Basketball Backstop | BN5: Ball Court
G6: SANI | H6: BA | I6: NULL | J6: NULL | K6: NULL | L6: NULL | M6: NULL | N6: NULL | O6: NULL | P6: NULL | Q6: NULL | R6: NULL | S6: NULL | T6: NULL | U6: NULL | V6: NULL | W6: NULL | X6: NULL | Y6: NULL | Z6: NULL | AA6: NULL | AB6: NULL | AC6: NULL | AD6: NULL | AE6: NULL | AF6: NULL | AG6: NULL | AH6: NULL | AI6: NULL | AJ6: NULL | AK6: NULL | AL6: NULL | AM6: NULL | AN6: NULL | AO6: NULL | AP6: NULL | AQ6: NULL | AR6: NULL | AS6: NULL | AT6: NULL | AU6: NULL | AV6: NULL | AW6: NULL | AX6: =IF(COUNTIF('ACTION Element Code Table'!$A:$A,G6&"_"&H6&"_"&I6&"_"&J6)=1,VLOOKUP(G6&"_"&H6&"_"&I6&"_"&J6,'ACTION Element Code Table'!$A:$C,3,FALSE),IF(G6&"_"&H6&"_"&I6&"_"&J6="NULL_NULL_NULL_NULL","NULL","Not exist in ACTION Element Code Table")) -> BATH TUBE | AY6: =IF(COUNTIF('ACTION Element Code Table'!$A:$A,N6&"_"&O6&"_"&P6&"_"&Q6)=1,VLOOKUP(N6&"_"&O6&"_"&P6&"_"&Q6,'ACTION Element Code Table'!$A:$C,3,FALSE),IF(N6&"_"&O6&"_"&P6&"_"&Q6="NULL_NULL_NULL_NULL","NULL","Not exist in ACTION Element Code Table")) -> NULL | AZ6: =IF(COUNTIF('ACTION Element Code Table'!$A:$A,U6&"_"&V6&"_"&W6&"_"&X6)=1,VLOOKUP(U6&"_"&V6&"_"&W6&"_"&X6,'ACTION Element Code Table'!$A:$C,3,FALSE),IF(U6&"_"&V6&"_"&W6&"_"&X6="NULL_NULL_NULL_NULL","NULL","Not exist in ACTION Element Code Table")) -> NULL | BA6: =IF(COUNTIF('ACTION Element Code Table'!$A:$A,AB6&"_"&AC6&"_"&AD6&"_"&AE6)=1,VLOOKUP(AB6&"_"&AC6&"_"&AD6&"_"&AE6,'ACTION Element Code Table'!$A:$C,3,FALSE),IF(AB6&"_"&AC6&"_"&AD6&"_"&AE6="NULL_NULL_NULL_NULL","NULL","Not exist in ACTION Element Code Table")) -> NULL | BB6: =IF(COUNTIF('ACTION Element Code Table'!$A:$A,AI6&"_"&AJ6&"_"&AK6&"_"&AL6)=1,VLOOKUP(AI6&"_"&AJ6&"_"&AK6&"_"&AL6,'ACTION Element Code Table'!$A:$C,3,FALSE),IF(AI6&"_"&AJ6&"_"&AK6&"_"&AL6="NULL_NULL_NULL_NULL","NULL","Not exist in ACTION Element Code Table")) -> NULL | BC6: =D6&E6&G6&H6&I6&J6&F6 -> SANIBANULLNULL | BD6: =D6&E6&N6&O6&P6&Q6&F6 -> NULLNULLNULLNULL | BE6: =D6&E6&U6&V6&W6&X6&F6 -> NULLNULLNULLNULL | BF6: =D6&E6&AB6&AC6&AD6&AE6&F6 -> NULLNULLNULLNULL | BG6: =D6&E6&AI6&AJ6&AK6&AL6&F6 -> NULLNULLNULLNULL | BH6: =IF(COUNTIF($BB:$BF,BC6)>1,"Duplicated","") | BI6: =IF(COUNTIF($BB:$BF,BD6)>1,"Duplicated","") -> Duplicated | BJ6: =IF(COUNTIF($BB:$BF,BE6)>1,"Duplicated","") -> Duplicated | BK6: =IF(COUNTIF($BB:$BF,BF6)>1,"Duplicated","") -> Duplicated | BL6: =IF(COUNTIF($BB:$BF,BG6)>1,"Duplicated","") -> Duplicated | BM6: Bathtube | BN6: Toilet Fixture
G7: FF | H7: FFOT | I7: NULL | J7: NULL | K7: NULL | L7: NULL | M7: NULL | N7: NULL | O7: NULL | P7: NULL | Q7: NULL | R7: NULL | S7: NULL | T7: NULL | U7: NULL | V7: NULL | W7: NULL | X7: NULL | Y7: NULL | Z7: NULL | AA7: NULL | AB7: NULL | AC7: NULL | AD7: NULL | AE7: NULL | AF7: NULL | AG7: NULL | AH7: NULL | AI7: NULL | AJ7: NULL | AK7: NULL | AL7: NULL | AM7: NULL | AN7: NULL | AO7: NULL | AP7: NULL | AQ7: NULL | AR7: NULL | AS7: NULL | AT7: NULL | AU7: NULL | AV7: NULL | AW7: NULL | AX7: =IF(COUNTIF('ACTION Element Code Table'!$A:$A,G7&"_"&H7&"_"&I7&"_"&J7)=1,VLOOKUP(G7&"_"&H7&"_"&I7&"_"&J7,'ACTION Element Code Table'!$A:$C,3,FALSE),IF(G7&"_"&H7&"_"&I7&"_"&J7="NULL_NULL_NULL_NULL","NULL","Not exist in ACTION Element Code Table")) -> OTHER FIXTURES & FITTING | AY7: =IF(COUNTIF('ACTION Element Code Table'!$A:$A,N7&"_"&O7&"_"&P7&"_"&Q7)=1,VLOOKUP(N7&"_"&O7&"_"&P7&"_"&Q7,'ACTION Element Code Table'!$A:$C,3,FALSE),IF(N7&"_"&O7&"_"&P7&"_"&Q7="NULL_NULL_NULL_NULL","NULL","Not exist in ACTION Element Code Table")) -> NULL | AZ7: =IF(COUNTIF('ACTION Element Code Table'!$A:$A,U7&"_"&V7&"_"&W7&"_"&X7)=1,VLOOKUP(U7&"_"&V7&"_"&W7&"_"&X7,'ACTION Element Code Table'!$A:$C,3,FALSE),IF(U7&"_"&V7&"_"&W7&"_"&X7="NULL_NULL_NULL_NULL","NULL","Not exist in ACTION Element Code Table")) -> NULL | BA7: =IF(COUNTIF('ACTION Element Code Table'!$A:$A,AB7&"_"&AC7&"_"&AD7&"_"&AE7)=1,VLOOKUP(AB7&"_"&AC7&"_"&AD7&"_"&AE7,'ACTION Element Code Table'!$A:$C,3,FALSE),IF(AB7&"_"&AC7&"_"&AD7&"_"&AE7="NULL_NULL_NULL_NULL","NULL","Not exist in ACTION Element Code Table")) -> NULL | BB7: =IF(COUNTIF('ACTION Element Code Table'!$A:$A,AI7&"_"&AJ7&"_"&AK7&"_"&AL7)=1,VLOOKUP(AI7&"_"&AJ7&"_"&AK7&"_"&AL7,'ACTION Element Code Table'!$A:$C,3,FALSE),IF(AI7&"_"&AJ7&"_"&AK7&"_"&AL7="NULL_NULL_NULL_NULL","NULL","Not exist in ACTION Element Code Table")) -> NULL | BC7: =D7&E7&G7&H7&I7&J7&F7 -> FFFFOTNULLNULL | BD7: =D7&E7&N7&O7&P7&Q7&F7 -> NULLNULLNULLNULL | BE7: =D7&E7&U7&V7&W7&X7&F7 -> NULLNULLNULLNULL | BF7: =D7&E7&AB7&AC7&AD7&AE7&F7 -> NULLNULLNULLNULL | BG7: =D7&E7&AI7&AJ7&AK7&AL7&F7 -> NULLNULLNULLNULL | BH7: =IF(COUNTIF($BB:$BF,BC7)>1,"Duplicated","") -> Duplicated | BI7: =IF(COUNTIF($BB:$BF,BD7)>1,"Duplicated","") -> Duplicated | BJ7: =IF(COUNTIF($BB:$BF,BE7)>1,"Duplicated","") -> Duplicated | BK7: =IF(COUNTIF($BB:$BF,BF7)>1,"Duplicated","") -> Duplicated | BL7: =IF(COUNTIF($BB:$BF,BG7)>1,"Duplicated","") -> Duplicated | BM7: Bed | BN7: Fixture
G8: FUR | H8: BEN | I8: NULL | J8: NULL | K8: NULL | L8: NULL | M8: NULL | N8: NULL | O8: NULL | P8: NULL | Q8: NULL | R8: NULL | S8: NULL | T8: NULL | U8: NULL | V8: NULL | W8: NULL | X8: NULL | Y8: NULL | Z8: NULL | AA8: NULL | AB8: NULL | AC8: NULL | AD8: NULL | AE8: NULL | AF8: NULL | AG8: NULL | AH8: NULL | AI8: NULL | AJ8: NULL | AK8: NULL | AL8: NULL | AM8: NULL | AN8: NULL | AO8: NULL | AP8: NULL | AQ8: NULL | AR8: NULL | AS8: NULL | AT8: NULL | AU8: NULL | AV8: NULL | AW8: NULL | AX8: =IF(COUNTIF('ACTION Element Code Table'!$A:$A,G8&"_"&H8&"_"&I8&"_"&J8)=1,VLOOKUP(G8&"_"&H8&"_"&I8&"_"&J8,'ACTION Element Code Table'!$A:$C,3,FALSE),IF(G8&"_"&H8&"_"&I8&"_"&J8="NULL_NULL_NULL_NULL","NULL","Not exist in ACTION Element Code Table")) -> FIXED BENCH | AY8: =IF(COUNTIF('ACTION Element Code Table'!$A:$A,N8&"_"&O8&"_"&P8&"_"&Q8)=1,VLOOKUP(N8&"_"&O8&"_"&P8&"_"&Q8,'ACTION Element Code Table'!$A:$C,3,FALSE),IF(N8&"_"&O8&"_"&P8&"_"&Q8="NULL_NULL_NULL_NULL","NULL","Not exist in ACTION Element Code Table")) -> NULL | AZ8: =IF(COUNTIF('ACTION Element Code Table'!$A:$A,U8&"_"&V8&"_"&W8&"_"&X8)=1,VLOOKUP(U8&"_"&V8&"_"&W8&"_"&X8,'ACTION Element Code Table'!$A:$C,3,FALSE),IF(U8&"_"&V8&"_"&W8&"_"&X8="NULL_NULL_NULL_NULL","NULL","Not exist in ACTION Element Code Table")) -> NULL | BA8: =IF(COUNTIF('ACTION Element Code Table'!$A:$A,AB8&"_"&AC8&"_"&AD8&"_"&AE8)=1,VLOOKUP(AB8&"_"&AC8&"_"&AD8&"_"&AE8,'ACTION Element Code Table'!$A:$C,3,FALSE),IF(AB8&"_"&AC8&"_"&AD8&"_"&AE8="NULL_NULL_NULL_NULL","NULL","Not exist in ACTION Element Code Table")) -> NULL | BB8: =IF(COUNTIF('ACTION Element Code Table'!$A:$A,AI8&"_"&AJ8&"_"&AK8&"_"&AL8)=1,VLOOKUP(AI8&"_"&AJ8&"_"&AK8&"_"&AL8,'ACTION Element Code Table'!$A:$C,3,FALSE),IF(AI8&"_"&AJ8&"_"&AK8&"_"&AL8="NULL_NULL_NULL_NULL","NULL","Not exist in ACTION Element Code Table")) -> NULL | BC8: =D8&E8&G8&H8&I8&J8&F8 -> FURBENNULLNULL | BD8: =D8&E8&N8&O8&P8&Q8&F8 -> NULLNULLNULLNULL | BE8: =D8&E8&U8&V8&W8&X8&F8 -> NULLNULLNULLNULL | BF8: =D8&E8&AB8&AC8&AD8&AE8&F8 -> NULLNULLNULLNULL | BG8: =D8&E8&AI8&AJ8&AK8&AL8&F8 -> NULLNULLNULLNULL | BH8: =IF(COUNTIF($BB:$BF,BC8)>1,"Duplicated","") | BI8: =IF(COUNTIF($BB:$BF,BD8)>1,"Duplicated","") -> Duplicated | BJ8: =IF(COUNTIF($BB:$BF,BE8)>1,"Duplicated","") -> Duplicated | BK8: =IF(COUNTIF($BB:$BF,BF8)>1,"Duplicated","") -> Duplicated | BL8: =IF(COUNTIF($BB:$BF,BG8)>1,"Duplicated","") -> Duplicated | BM8: Bench | BN8: Bench
G9: STR | H9: WL | I9: STRU | J9: BR | K9: NULL | L9: NULL | M9: NULL | N9: NULL | O9: NULL | P9: NULL | Q9: NULL | R9: NULL | S9: NULL | T9: NULL | U9: NULL | V9: NULL | W9: NULL | X9: NULL | Y9: NULL | Z9: NULL | AA9: NULL | AB9: NULL | AC9: NULL | AD9: NULL | AE9: NULL | AF9: NULL | AG9: NULL | AH9: NULL | AI9: NULL | AJ9: NULL | AK9: NULL | AL9: NULL | AM9: NULL | AN9: NULL | AO9: NULL | AP9: NULL | AQ9: NULL | AR9: NULL | AS9: NULL | AT9: NULL | AU9: NULL | AV9: NULL | AW9: NULL | AX9: =IF(COUNTIF('ACTION Element Code Table'!$A:$A,G9&"_"&H9&"_"&I9&"_"&J9)=1,VLOOKUP(G9&"_"&H9&"_"&I9&"_"&J9,'ACTION Element Code Table'!$A:$C,3,FALSE),IF(G9&"_"&H9&"_"&I9&"_"&J9="NULL_NULL_NULL_NULL","NULL","Not exist in ACTION Element Code Table")) -> BRICK WALL | AY9: =IF(COUNTIF('ACTION Element Code Table'!$A:$A,N9&"_"&O9&"_"&P9&"_"&Q9)=1,VLOOKUP(N9&"_"&O9&"_"&P9&"_"&Q9,'ACTION Element Code Table'!$A:$C,3,FALSE),IF(N9&"_"&O9&"_"&P9&"_"&Q9="NULL_NULL_NULL_NULL","NULL","Not exist in ACTION Element Code Table")) -> NULL | AZ9: =IF(COUNTIF('ACTION Element Code Table'!$A:$A,U9&"_"&V9&"_"&W9&"_"&X9)=1,VLOOKUP(U9&"_"&V9&"_"&W9&"_"&X9,'ACTION Element Code Table'!$A:$C,3,FALSE),IF(U9&"_"&V9&"_"&W9&"_"&X9="NULL_NULL_NULL_NULL","NULL","Not exist in ACTION Element Code Table")) -> NULL | BA9: =IF(COUNTIF('ACTION Element Code Table'!$A:$A,AB9&"_"&AC9&"_"&AD9&"_"&AE9)=1,VLOOKUP(AB9&"_"&AC9&"_"&AD9&"_"&AE9,'ACTION Element Code Table'!$A:$C,3,FALSE),IF(AB9&"_"&AC9&"_"&AD9&"_"&AE9="NULL_NULL_NULL_NULL","NULL","Not exist in ACTION Element Code Table")) -> NULL | BB9: =IF(COUNTIF('ACTION Element Code Table'!$A:$A,AI9&"_"&AJ9&"_"&AK9&"_"&AL9)=1,VLOOKUP(AI9&"_"&AJ9&"_"&AK9&"_"&AL9,'ACTION Element Code Table'!$A:$C,3,FALSE),IF(AI9&"_"&AJ9&"_"&AK9&"_"&AL9="NULL_NULL_NULL_NULL","NULL","Not exist in ACTION Element Code Table")) -> NULL | BC9: =D9&E9&G9&H9&I9&J9&F9 -> STRWLSTRUBR | BD9: =D9&E9&N9&O9&P9&Q9&F9 -> NULLNULLNULLNULL | BE9: =D9&E9&U9&V9&W9&X9&F9 -> NULLNULLNULLNULL | BF9: =D9&E9&AB9&AC9&AD9&AE9&F9 -> NULLNULLNULLNULL | BG9: =D9&E9&AI9&AJ9&AK9&AL9&F9 -> NULLNULLNULLNULL | BH9: =IF(COUNTIF($BB:$BF,BC9)>1,"Duplicated","") | BM9: Brick Wall | BN9: Brick Wall
G10: STR | H10: CANO | I10: NULL | J10: NULL | K10: NULL | L10: NULL | M10: NULL | N10: NULL | O10: NULL | P10: NULL | Q10: NULL | R10: NULL | S10: NULL | T10: NULL | U10: NULL | V10: NULL | W10: NULL | X10: NULL | Y10: NULL | Z10: NULL | AA10: NULL | AB10: NULL | AC10: NULL | AD10: NULL | AE10: NULL | AF10: NULL | AG10: NULL | AH10: NULL | AI10: NULL | AJ10: NULL | AK10: NULL | AL10: NULL | AM10: NULL | AN10: NULL | AO10: NULL | AP10: NULL | AQ10: NULL | AR10: NULL | AS10: NULL | AT10: NULL | AU10: NULL | AV10: NULL | AW10: NULL | AX10: =IF(COUNTIF('ACTION Element Code Table'!$A:$A,G10&"_"&H10&"_"&I10&"_"&J10)=1,VLOOKUP(G10&"_"&H10&"_"&I10&"_"&J10,'ACTION Element Code Table'!$A:$C,3,FALSE),IF(G10&"_"&H10&"_"&I10&"_"&J10="NULL_NULL_NULL_NULL","NULL","Not exist in ACTION Element Code Table")) -> CANOPY | AY10: =IF(COUNTIF('ACTION Element Code Table'!$A:$A,N10&"_"&O10&"_"&P10&"_"&Q10)=1,VLOOKUP(N10&"_"&O10&"_"&P10&"_"&Q10,'ACTION Element Code Table'!$A:$C,3,FALSE),IF(N10&"_"&O10&"_"&P10&"_"&Q10="NULL_NULL_NULL_NULL","NULL","Not exist in ACTION Element Code Table")) -> NULL | AZ10: =IF(COUNTIF('ACTION Element Code Table'!$A:$A,U10&"_"&V10&"_"&W10&"_"&X10)=1,VLOOKUP(U10&"_"&V10&"_"&W10&"_"&X10,'ACTION Element Code Table'!$A:$C,3,FALSE),IF(U10&"_"&V10&"_"&W10&"_"&X10="NULL_NULL_NULL_NULL","NULL","Not exist in ACTION Element Code Table")) -> NULL | BA10: =IF(COUNTIF('ACTION Element Code Table'!$A:$A,AB10&"_"&AC10&"_"&AD10&"_"&AE10)=1,VLOOKUP(AB10&"_"&AC10&"_"&AD10&"_"&AE10,'ACTION Element Code Table'!$A:$C,3,FALSE),IF(AB10&"_"&AC10&"_"&AD10&"_"&AE10="NULL_NULL_NULL_NULL","NULL","Not exist in ACTION Element Code Table")) -> NULL | BB10: =IF(COUNTIF('ACTION Element Code Table'!$A:$A,AI10&"_"&AJ10&"_"&AK10&"_"&AL10)=1,VLOOKUP(AI10&"_"&AJ10&"_"&AK10&"_"&AL10,'ACTION Element Code Table'!$A:$C,3,FALSE),IF(AI10&"_"&AJ10&"_"&AK10&"_"&AL10="NULL_NULL_NULL_NULL","NULL","Not exist in ACTION Element Code Table")) -> NULL | BC10: =D10&E10&G10&H10&I10&J10&F10 -> STRCANONULLNULL | BD10: =D10&E10&N10&O10&P10&Q10&F10 -> NULLNULLNULLNULL | BE10: =D10&E10&U10&V10&W10&X10&F10 -> NULLNULLNULLNULL | BF10: =D10&E10&AB10&AC10&AD10&AE10&F10 -> NULLNULLNULLNULL | BG10: =D10&E10&AI10&AJ10&AK10&AL10&F10 -> NULLNULLNULLNULL | BH10: =IF(COUNTIF($BB:$BF,BC10)>1,"Duplicated","") | BI10: =IF(COUNTIF($BB:$BF,BD10)>1,"Duplicated","") -> Duplicated | BJ10: =IF(COUNTIF($BB:$BF,BE10)>1,"Duplicated","") -> Duplicated | BK10: =IF(COUNTIF($BB:$BF,BF10)>1,"Duplicated","") -> Duplicated | BL10: =IF(COUNTIF($BB:$BF,BG10)>1,"Duplicated","") -> Duplicated | BM10: Canopy | BN10: Canopy
G11: STR | H11: LAD | I11: NULL | J11: NULL | K11: NULL | L11: NULL | M11: NULL | N11: NULL | O11: NULL | P11: NULL | Q11: NULL | R11: NULL | S11: NULL | T11: NULL | U11: NULL | V11: NULL | W11: NULL | X11: NULL | Y11: NULL | Z11: NULL | AA11: NULL | AB11: NULL | AC11: NULL | AD11: NULL | AE11: NULL | AF11: NULL | AG11: NULL | AH11: NULL | AI11: NULL | AJ11: NULL | AK11: NULL | AL11: NULL | AM11: NULL | AN11: NULL | AO11: NULL | AP11: NULL | AQ11: NULL | AR11: NULL | AS11: NULL | AT11: NULL | AU11: NULL | AV11: NULL | AW11: NULL | AX11: =IF(COUNTIF('ACTION Element Code Table'!$A:$A,G11&"_"&H11&"_"&I11&"_"&J11)=1,VLOOKUP(G11&"_"&H11&"_"&I11&"_"&J11,'ACTION Element Code Table'!$A:$C,3,FALSE),IF(G11&"_"&H11&"_"&I11&"_"&J11="NULL_NULL_NULL_NULL","NULL","Not exist in ACTION Element Code Table")) -> LADDER | AY11: =IF(COUNTIF('ACTION Element Code Table'!$A:$A,N11&"_"&O11&"_"&P11&"_"&Q11)=1,VLOOKUP(N11&"_"&O11&"_"&P11&"_"&Q11,'ACTION Element Code Table'!$A:$C,3,FALSE),IF(N11&"_"&O11&"_"&P11&"_"&Q11="NULL_NULL_NULL_NULL","NULL","Not exist in ACTION Element Code Table")) -> NULL | AZ11: =IF(COUNTIF('ACTION Element Code Table'!$A:$A,U11&"_"&V11&"_"&W11&"_"&X11)=1,VLOOKUP(U11&"_"&V11&"_"&W11&"_"&X11,'ACTION Element Code Table'!$A:$C,3,FALSE),IF(U11&"_"&V11&"_"&W11&"_"&X11="NULL_NULL_NULL_NULL","NULL","Not exist in ACTION Element Code Table")) -> NULL | BA11: =IF(COUNTIF('ACTION Element Code Table'!$A:$A,AB11&"_"&AC11&"_"&AD11&"_"&AE11)=1,VLOOKUP(AB11&"_"&AC11&"_"&AD11&"_"&AE11,'ACTION Element Code Table'!$A:$C,3,FALSE),IF(AB11&"_"&AC11&"_"&AD11&"_"&AE11="NULL_NULL_NULL_NULL","NULL","Not exist in ACTION Element Code Table")) -> NULL | BB11: =IF(COUNTIF('ACTION Element Code Table'!$A:$A,AI11&"_"&AJ11&"_"&AK11&"_"&AL11)=1,VLOOKUP(AI11&"_"&AJ11&"_"&AK11&"_"&AL11,'ACTION Element Code Table'!$A:$C,3,FALSE),IF(AI11&"_"&AJ11&"_"&AK11&"_"&AL11="NULL_NULL_NULL_NULL","NULL","Not exist in ACTION Element Code Table")) -> NULL | BC11: =D11&E11&G11&H11&I11&J11&F11 -> STRLADNULLNULL | BD11: =D11&E11&N11&O11&P11&Q11&F11 -> NULLNULLNULLNULL | BE11: =D11&E11&U11&V11&W11&X11&F11 -> NULLNULLNULLNULL | BF11: =D11&E11&AB11&AC11&AD11&AE11&F11 -> NULLNULLNULLNULL | BG11: =D11&E11&AI11&AJ11&AK11&AL11&F11 -> NULLNULLNULLNULL | BH11: =IF(COUNTIF($BB:$BF,BC11)>1,"Duplicated","") | BM11: Cat Ladder | BN11: Fixture
G12: FF | H12: WLCUR | I12: FRM | J12: NULL | K12: NULL | L12: NULL | M12: NULL | N12: NULL | O12: NULL | P12: NULL | Q12: NULL | R12: NULL | S12: NULL | T12: NULL | U12: NULL | V12: NULL | W12: NULL | X12: NULL | Y12: NULL | Z12: NULL | AA12: NULL | AB12: NULL | AC12: NULL | AD12: NULL | AE12: NULL | AF12: NULL | AG12: NULL | AH12: NULL | AI12: NULL | AJ12: NULL | AK12: NULL | AL12: NULL | AM12: NULL | AN12: NULL | AO12: NULL | AP12: NULL | AQ12: NULL | AR12: NULL | AS12: NULL | AT12: NULL | AU12: NULL | AV12: NULL | AW12: NULL | AX12: =IF(COUNTIF('ACTION Element Code Table'!$A:$A,G12&"_"&H12&"_"&I12&"_"&J12)=1,VLOOKUP(G12&"_"&H12&"_"&I12&"_"&J12,'ACTION Element Code Table'!$A:$C,3,FALSE),IF(G12&"_"&H12&"_"&I12&"_"&J12="NULL_NULL_NULL_NULL","NULL","Not exist in ACTION Element Code Table")) -> FRAME OF CURTAIN WALLING | AY12: =IF(COUNTIF('ACTION Element Code Table'!$A:$A,N12&"_"&O12&"_"&P12&"_"&Q12)=1,VLOOKUP(N12&"_"&O12&"_"&P12&"_"&Q12,'ACTION Element Code Table'!$A:$C,3,FALSE),IF(N12&"_"&O12&"_"&P12&"_"&Q12="NULL_NULL_NULL_NULL","NULL","Not exist in ACTION Element Code Table")) -> NULL | AZ12: =IF(COUNTIF('ACTION Element Code Table'!$A:$A,U12&"_"&V12&"_"&W12&"_"&X12)=1,VLOOKUP(U12&"_"&V12&"_"&W12&"_"&X12,'ACTION Element Code Table'!$A:$C,3,FALSE),IF(U12&"_"&V12&"_"&W12&"_"&X12="NULL_NULL_NULL_NULL","NULL","Not exist in ACTION Element Code Table")) -> NULL | BA12: =IF(COUNTIF('ACTION Element Code Table'!$A:$A,AB12&"_"&AC12&"_"&AD12&"_"&AE12)=1,VLOOKUP(AB12&"_"&AC12&"_"&AD12&"_"&AE12,'ACTION Element Code Table'!$A:$C,3,FALSE),IF(AB12&"_"&AC12&"_"&AD12&"_"&AE12="NULL_NULL_NULL_NULL","NULL","Not exist in ACTION Element Code Table")) -> NULL | BB12: =IF(COUNTIF('ACTION Element Code Table'!$A:$A,AI12&"_"&AJ12&"_"&AK12&"_"&AL12)=1,VLOOKUP(AI12&"_"&AJ12&"_"&AK12&"_"&AL12,'ACTION Element Code Table'!$A:$C,3,FALSE),IF(AI12&"_"&AJ12&"_"&AK12&"_"&AL12="NULL_NULL_NULL_NULL","NULL","Not exist in ACTION Element Code Table")) -> NULL | BC12: =D12&E12&G12&H12&I12&J12&F12 -> FFWLCURFRMNULL | BD12: =D12&E12&N12&O12&P12&Q12&F12 -> NULLNULLNULLNULL | BE12: =D12&E12&U12&V12&W12&X12&F12 -> NULLNULLNULLNULL | BF12: =D12&E12&AB12&AC12&AD12&AE12&F12 -> NULLNULLNULLNULL | BG12: =D12&E12&AI12&AJ12&AK12&AL12&F12 -> NULLNULLNULLNULL | BH12: =IF(COUNTIF($BB:$BF,BC12)>1,"Duplicated","") | BI12: =IF(COUNTIF($BB:$BF,BD12)>1,"Duplicated","") -> Duplicated | BJ12: =IF(COUNTIF($BB:$BF,BE12)>1,"Duplicated","") -> Duplicated | BK12: =IF(COUNTIF($BB:$BF,BF12)>1,"Duplicated","") -> Duplicated | BL12: =IF(COUNTIF($BB:$BF,BG12)>1,"Duplicated","") -> Duplicated | BM12: Cladding | BN12: Curtain Wall
G13: FF | H13: DR | I13: STRU | J13: OTH | K13: NULL | L13: NULL | M13: Access Panel | N13: NULL | O13: NULL | P13: NULL | Q13: NULL | R13: NULL | S13: NULL | T13: NULL | U13: NULL | V13: NULL | W13: NULL | X13: NULL | Y13: NULL | Z13: NULL | AA13: NULL | AB13: NULL | AC13: NULL | AD13: NULL | AE13: NULL | AF13: NULL | AG13: NULL | AH13: NULL | AI13: NULL | AJ13: NULL | AK13: NULL | AL13: NULL | AM13: NULL | AN13: NULL | AO13: NULL | AP13: NULL | AQ13: NULL | AR13: NULL | AS13: NULL | AT13: NULL | AU13: NULL | AV13: NULL | AW13: NULL | AX13: =IF(COUNTIF('ACTION Element Code Table'!$A:$A,G13&"_"&H13&"_"&I13&"_"&J13)=1,VLOOKUP(G13&"_"&H13&"_"&I13&"_"&J13,'ACTION Element Code Table'!$A:$C,3,FALSE),IF(G13&"_"&H13&"_"&I13&"_"&J13="NULL_NULL_NULL_NULL","NULL","Not exist in ACTION Element Code Table")) -> DOOR (SEE REMARKS) | AY13: =IF(COUNTIF('ACTION Element Code Table'!$A:$A,N13&"_"&O13&"_"&P13&"_"&Q13)=1,VLOOKUP(N13&"_"&O13&"_"&P13&"_"&Q13,'ACTION Element Code Table'!$A:$C,3,FALSE),IF(N13&"_"&O13&"_"&P13&"_"&Q13="NULL_NULL_NULL_NULL","NULL","Not exist in ACTION Element Code Table")) -> NULL | AZ13: =IF(COUNTIF('ACTION Element Code Table'!$A:$A,U13&"_"&V13&"_"&W13&"_"&X13)=1,VLOOKUP(U13&"_"&V13&"_"&W13&"_"&X13,'ACTION Element Code Table'!$A:$C,3,FALSE),IF(U13&"_"&V13&"_"&W13&"_"&X13="NULL_NULL_NULL_NULL","NULL","Not exist in ACTION Element Code Table")) -> NULL | BA13: =IF(COUNTIF('ACTION Element Code Table'!$A:$A,AB13&"_"&AC13&"_"&AD13&"_"&AE13)=1,VLOOKUP(AB13&"_"&AC13&"_"&AD13&"_"&AE13,'ACTION Element Code Table'!$A:$C,3,FALSE),IF(AB13&"_"&AC13&"_"&AD13&"_"&AE13="NULL_NULL_NULL_NULL","NULL","Not exist in ACTION Element Code Table")) -> NULL | BB13: =IF(COUNTIF('ACTION Element Code Table'!$A:$A,AI13&"_"&AJ13&"_"&AK13&"_"&AL13)=1,VLOOKUP(AI13&"_"&AJ13&"_"&AK13&"_"&AL13,'ACTION Element Code Table'!$A:$C,3,FALSE),IF(AI13&"_"&AJ13&"_"&AK13&"_"&AL13="NULL_NULL_NULL_NULL","NULL","Not exist in ACTION Element Code Table")) -> NULL | BC13: =D13&E13&G13&H13&I13&J13&F13 -> FFDRSTRUOTH | BD13: =D13&E13&N13&O13&P13&Q13&F13 -> NULLNULLNULLNULL | BE13: =D13&E13&U13&V13&W13&X13&F13 -> NULLNULLNULLNULL | BF13: =D13&E13&AB13&AC13&AD13&AE13&F13 -> NULLNULLNULLNULL | BG13: =D13&E13&AI13&AJ13&AK13&AL13&F13 -> NULLNULLNULLNULL | BH13: =IF(COUNTIF($BB:$BF,BC13)>1,"Duplicated","") -> Duplicated | BI13: =IF(COUNTIF($BB:$BF,BD13)>1,"Duplicated","") -> Duplicated | BJ13: =IF(COUNTIF($BB:$BF,BE13)>1,"Duplicated","") -> Duplicated | BK13: =IF(COUNTIF($BB:$BF,BF13)>1,"Duplicated","") -> Duplicated | BL13: =IF(COUNTIF($BB:$BF,BG13)>1,"Duplicated","") -> Duplicated | BM13: Access Panel
G14: FF | H14: DR | I14: STRU | J14: OTH | K14: NULL | L14: NULL | M14: Double Equal Door | N14: NULL | O14: NULL | P14: NULL | Q14: NULL | R14: NULL | S14: NULL | T14: NULL | U14: NULL | V14: NULL | W14: NULL | X14: NULL | Y14: NULL | Z14: NULL | AA14: NULL | AB14: NULL | AC14: NULL | AD14: NULL | AE14: NULL | AF14: NULL | AG14: NULL | AH14: NULL | AI14: NULL | AJ14: NULL | AK14: NULL | AL14: NULL | AM14: NULL | AN14: NULL | AO14: NULL | AP14: NULL | AQ14: NULL | AR14: NULL | AS14: NULL | AT14: NULL | AU14: NULL | AV14: NULL | AW14: NULL | AX14: =IF(COUNTIF('ACTION Element Code Table'!$A:$A,G14&"_"&H14&"_"&I14&"_"&J14)=1,VLOOKUP(G14&"_"&H14&"_"&I14&"_"&J14,'ACTION Element Code Table'!$A:$C,3,FALSE),IF(G14&"_"&H14&"_"&I14&"_"&J14="NULL_NULL_NULL_NULL","NULL","Not exist in ACTION Element Code Table")) -> DOOR (SEE REMARKS) | AY14: =IF(COUNTIF('ACTION Element Code Table'!$A:$A,N14&"_"&O14&"_"&P14&"_"&Q14)=1,VLOOKUP(N14&"_"&O14&"_"&P14&"_"&Q14,'ACTION Element Code Table'!$A:$C,3,FALSE),IF(N14&"_"&O14&"_"&P14&"_"&Q14="NULL_NULL_NULL_NULL","NULL","Not exist in ACTION Element Code Table")) -> NULL | AZ14: =IF(COUNTIF('ACTION Element Code Table'!$A:$A,U14&"_"&V14&"_"&W14&"_"&X14)=1,VLOOKUP(U14&"_"&V14&"_"&W14&"_"&X14,'ACTION Element Code Table'!$A:$C,3,FALSE),IF(U14&"_"&V14&"_"&W14&"_"&X14="NULL_NULL_NULL_NULL","NULL","Not exist in ACTION Element Code Table")) -> NULL | BA14: =IF(COUNTIF('ACTION Element Code Table'!$A:$A,AB14&"_"&AC14&"_"&AD14&"_"&AE14)=1,VLOOKUP(AB14&"_"&AC14&"_"&AD14&"_"&AE14,'ACTION Element Code Table'!$A:$C,3,FALSE),IF(AB14&"_"&AC14&"_"&AD14&"_"&AE14="NULL_NULL_NULL_NULL","NULL","Not exist in ACTION Element Code Table")) -> NULL | BB14: =IF(COUNTIF('ACTION Element Code Table'!$A:$A,AI14&"_"&AJ14&"_"&AK14&"_"&AL14)=1,VLOOKUP(AI14&"_"&AJ14&"_"&AK14&"_"&AL14,'ACTION Element Code Table'!$A:$C,3,FALSE),IF(AI14&"_"&AJ14&"_"&AK14&"_"&AL14="NULL_NULL_NULL_NULL","NULL","Not exist in ACTION Element Code Table")) -> NULL | BC14: =D14&E14&G14&H14&I14&J14&F14 -> FFDRSTRUOTH | BD14: =D14&E14&N14&O14&P14&Q14&F14 -> NULLNULLNULLNULL | BE14: =D14&E14&U14&V14&W14&X14&F14 -> NULLNULLNULLNULL | BF14: =D14&E14&AB14&AC14&AD14&AE14&F14 -> NULLNULLNULLNULL | BG14: =D14&E14&AI14&AJ14&AK14&AL14&F14 -> NULLNULLNULLNULL | BH14: =IF(COUNTIF($BB:$BF,BC14)>1,"Duplicated","") -> Duplicated | BI14: =IF(COUNTIF($BB:$BF,BD14)>1,"Duplicated","") -> Duplicated | BJ14: =IF(COUNTIF($BB:$BF,BE14)>1,"Duplicated","") -> Duplicated | BK14: =IF(COUNTIF($BB:$BF,BF14)>1,"Duplicated","") -> Duplicated | BL14: =IF(COUNTIF($BB:$BF,BG14)>1,"Duplicated","") -> Duplicated | BM14: Double Equal Door
G15: FF | H15: DR | I15: STRU | J15: OTH | K15: NULL | L15: NULL | M15: Double Uneqaul Door | N15: NULL | O15: NULL | P15: NULL | Q15: NULL | R15: NULL | S15: NULL | T15: NULL | U15: NULL | V15: NULL | W15: NULL | X15: NULL | Y15: NULL | Z15: NULL | AA15: NULL | AB15: NULL | AC15: NULL | AD15: NULL | AE15: NULL | AF15: NULL | AG15: NULL | AH15: NULL | AI15: NULL | AJ15: NULL | AK15: NULL | AL15: NULL | AM15: NULL | AN15: NULL | AO15: NULL | AP15: NULL | AQ15: NULL | AR15: NULL | AS15: NULL | AT15: NULL | AU15: NULL | AV15: NULL | AW15: NULL | AX15: =IF(COUNTIF('ACTION Element Code Table'!$A:$A,G15&"_"&H15&"_"&I15&"_"&J15)=1,VLOOKUP(G15&"_"&H15&"_"&I15&"_"&J15,'ACTION Element Code Table'!$A:$C,3,FALSE),IF(G15&"_"&H15&"_"&I15&"_"&J15="NULL_NULL_NULL_NULL","NULL","Not exist in ACTION Element Code Table")) -> DOOR (SEE REMARKS) | AY15: =IF(COUNTIF('ACTION Element Code Table'!$A:$A,N15&"_"&O15&"_"&P15&"_"&Q15)=1,VLOOKUP(N15&"_"&O15&"_"&P15&"_"&Q15,'ACTION Element Code Table'!$A:$C,3,FALSE),IF(N15&"_"&O15&"_"&P15&"_"&Q15="NULL_NULL_NULL_NULL","NULL","Not exist in ACTION Element Code Table")) -> NULL | AZ15: =IF(COUNTIF('ACTION Element Code Table'!$A:$A,U15&"_"&V15&"_"&W15&"_"&X15)=1,VLOOKUP(U15&"_"&V15&"_"&W15&"_"&X15,'ACTION Element Code Table'!$A:$C,3,FALSE),IF(U15&"_"&V15&"_"&W15&"_"&X15="NULL_NULL_NULL_NULL","NULL","Not exist in ACTION Element Code Table")) -> NULL | BA15: =IF(COUNTIF('ACTION Element Code Table'!$A:$A,AB15&"_"&AC15&"_"&AD15&"_"&AE15)=1,VLOOKUP(AB15&"_"&AC15&"_"&AD15&"_"&AE15,'ACTION Element Code Table'!$A:$C,3,FALSE),IF(AB15&"_"&AC15&"_"&AD15&"_"&AE15="NULL_NULL_NULL_NULL","NULL","Not exist in ACTION Element Code Table")) -> NULL | BB15: =IF(COUNTIF('ACTION Element Code Table'!$A:$A,AI15&"_"&AJ15&"_"&AK15&"_"&AL15)=1,VLOOKUP(AI15&"_"&AJ15&"_"&AK15&"_"&AL15,'ACTION Element Code Table'!$A:$C,3,FALSE),IF(AI15&"_"&AJ15&"_"&AK15&"_"&AL15="NULL_NULL_NULL_NULL","NULL","Not exist in ACTION Element Code Table")) -> NULL | BC15: =D15&E15&G15&H15&I15&J15&F15 -> FFDRSTRUOTH | BD15: =D15&E15&N15&O15&P15&Q15&F15 -> NULLNULLNULLNULL | BE15: =D15&E15&U15&V15&W15&X15&F15 -> NULLNULLNULLNULL | BF15: =D15&E15&AB15&AC15&AD15&AE15&F15 -> NULLNULLNULLNULL | BG15: =D15&E15&AI15&AJ15&AK15&AL15&F15 -> NULLNULLNULLNULL | BH15: =IF(COUNTIF($BB:$BF,BC15)>1,"Duplicated","") -> Duplicated | BI15: =IF(COUNTIF($BB:$BF,BD15)>1,"Duplicated","") -> Duplicated | BJ15: =IF(COUNTIF($BB:$BF,BE15)>1,"Duplicated","") -> Duplicated | BK15: =IF(COUNTIF($BB:$BF,BF15)>1,"Duplicated","") -> Duplicated | BL15: =IF(COUNTIF($BB:$BF,BG15)>1,"Duplicated","") -> Duplicated | BM15: Double Uneqaul Door
G16: FF | H16: DR | I16: STRU | J16: OTH | K16: NULL | L16: NULL | M16: Emergency door | N16: NULL | O16: NULL | P16: NULL | Q16: NULL | R16: NULL | S16: NULL | T16: NULL | U16: NULL | V16: NULL | W16: NULL | X16: NULL | Y16: NULL | Z16: NULL | AA16: NULL | AB16: NULL | AC16: NULL | AD16: NULL | AE16: NULL | AF16: NULL | AG16: NULL | AH16: NULL | AI16: NULL | AJ16: NULL | AK16: NULL | AL16: NULL | AM16: NULL | AN16: NULL | AO16: NULL | AP16: NULL | AQ16: NULL | AR16: NULL | AS16: NULL | AT16: NULL | AU16: NULL | AV16: NULL | AW16: NULL | AX16: =IF(COUNTIF('ACTION Element Code Table'!$A:$A,G16&"_"&H16&"_"&I16&"_"&J16)=1,VLOOKUP(G16&"_"&H16&"_"&I16&"_"&J16,'ACTION Element Code Table'!$A:$C,3,FALSE),IF(G16&"_"&H16&"_"&I16&"_"&J16="NULL_NULL_NULL_NULL","NULL","Not exist in ACTION Element Code Table")) -> DOOR (SEE REMARKS) | AY16: =IF(COUNTIF('ACTION Element Code Table'!$A:$A,N16&"_"&O16&"_"&P16&"_"&Q16)=1,VLOOKUP(N16&"_"&O16&"_"&P16&"_"&Q16,'ACTION Element Code Table'!$A:$C,3,FALSE),IF(N16&"_"&O16&"_"&P16&"_"&Q16="NULL_NULL_NULL_NULL","NULL","Not exist in ACTION Element Code Table")) -> NULL | AZ16: =IF(COUNTIF('ACTION Element Code Table'!$A:$A,U16&"_"&V16&"_"&W16&"_"&X16)=1,VLOOKUP(U16&"_"&V16&"_"&W16&"_"&X16,'ACTION Element Code Table'!$A:$C,3,FALSE),IF(U16&"_"&V16&"_"&W16&"_"&X16="NULL_NULL_NULL_NULL","NULL","Not exist in ACTION Element Code Table")) -> NULL | BA16: =IF(COUNTIF('ACTION Element Code Table'!$A:$A,AB16&"_"&AC16&"_"&AD16&"_"&AE16)=1,VLOOKUP(AB16&"_"&AC16&"_"&AD16&"_"&AE16,'ACTION Element Code Table'!$A:$C,3,FALSE),IF(AB16&"_"&AC16&"_"&AD16&"_"&AE16="NULL_NULL_NULL_NULL","NULL","Not exist in ACTION Element Code Table")) -> NULL | BB16: =IF(COUNTIF('ACTION Element Code Table'!$A:$A,AI16&"_"&AJ16&"_"&AK16&"_"&AL16)=1,VLOOKUP(AI16&"_"&AJ16&"_"&AK16&"_"&AL16,'ACTION Element Code Table'!$A:$C,3,FALSE),IF(AI16&"_"&AJ16&"_"&AK16&"_"&AL16="NULL_NULL_NULL_NULL","NULL","Not exist in ACTION Element Code Table")) -> NULL | BC16: =D16&E16&G16&H16&I16&J16&F16 -> FFDRSTRUOTH | BD16: =D16&E16&N16&O16&P16&Q16&F16 -> NULLNULLNULLNULL | BE16: =D16&E16&U16&V16&W16&X16&F16 -> NULLNULLNULLNULL | BF16: =D16&E16&AB16&AC16&AD16&AE16&F16 -> NULLNULLNULLNULL | BG16: =D16&E16&AI16&AJ16&AK16&AL16&F16 -> NULLNULLNULLNULL | BH16: =IF(COUNTIF($BB:$BF,BC16)>1,"Duplicated","") -> Duplicated | BI16: =IF(COUNTIF($BB:$BF,BD16)>1,"Duplicated","") -> Duplicated | BJ16: =IF(COUNTIF($BB:$BF,BE16)>1,"Duplicated","") -> Duplicated | BK16: =IF(COUNTIF($BB:$BF,BF16)>1,"Duplicated","") -> Duplicated | BL16: =IF(COUNTIF($BB:$BF,BG16)>1,"Duplicated","") -> Duplicated | BM16: Emergency door
G17: FF | H17: DR | I17: STRU | J17: OTH | K17: NULL | L17: NULL | M17: HR Door | N17: NULL | O17: NULL | P17: NULL | Q17: NULL | R17: NULL | S17: NULL | T17: NULL | U17: NULL | V17: NULL | W17: NULL | X17: NULL | Y17: NULL | Z17: NULL | AA17: NULL | AB17: NULL | AC17: NULL | AD17: NULL | AE17: NULL | AF17: NULL | AG17: NULL | AH17: NULL | AI17: NULL | AJ17: NULL | AK17: NULL | AL17: NULL | AM17: NULL | AN17: NULL | AO17: NULL | AP17: NULL | AQ17: NULL | AR17: NULL | AS17: NULL | AT17: NULL | AU17: NULL | AV17: NULL | AW17: NULL | AX17: =IF(COUNTIF('ACTION Element Code Table'!$A:$A,G17&"_"&H17&"_"&I17&"_"&J17)=1,VLOOKUP(G17&"_"&H17&"_"&I17&"_"&J17,'ACTION Element Code Table'!$A:$C,3,FALSE),IF(G17&"_"&H17&"_"&I17&"_"&J17="NULL_NULL_NULL_NULL","NULL","Not exist in ACTION Element Code Table")) -> DOOR (SEE REMARKS) | AY17: =IF(COUNTIF('ACTION Element Code Table'!$A:$A,N17&"_"&O17&"_"&P17&"_"&Q17)=1,VLOOKUP(N17&"_"&O17&"_"&P17&"_"&Q17,'ACTION Element Code Table'!$A:$C,3,FALSE),IF(N17&"_"&O17&"_"&P17&"_"&Q17="NULL_NULL_NULL_NULL","NULL","Not exist in ACTION Element Code Table")) -> NULL | AZ17: =IF(COUNTIF('ACTION Element Code Table'!$A:$A,U17&"_"&V17&"_"&W17&"_"&X17)=1,VLOOKUP(U17&"_"&V17&"_"&W17&"_"&X17,'ACTION Element Code Table'!$A:$C,3,FALSE),IF(U17&"_"&V17&"_"&W17&"_"&X17="NULL_NULL_NULL_NULL","NULL","Not exist in ACTION Element Code Table")) -> NULL | BA17: =IF(COUNTIF('ACTION Element Code Table'!$A:$A,AB17&"_"&AC17&"_"&AD17&"_"&AE17)=1,VLOOKUP(AB17&"_"&AC17&"_"&AD17&"_"&AE17,'ACTION Element Code Table'!$A:$C,3,FALSE),IF(AB17&"_"&AC17&"_"&AD17&"_"&AE17="NULL_NULL_NULL_NULL","NULL","Not exist in ACTION Element Code Table")) -> NULL | BB17: =IF(COUNTIF('ACTION Element Code Table'!$A:$A,AI17&"_"&AJ17&"_"&AK17&"_"&AL17)=1,VLOOKUP(AI17&"_"&AJ17&"_"&AK17&"_"&AL17,'ACTION Element Code Table'!$A:$C,3,FALSE),IF(AI17&"_"&AJ17&"_"&AK17&"_"&AL17="NULL_NULL_NULL_NULL","NULL","Not exist in ACTION Element Code Table")) -> NULL | BC17: =D17&E17&G17&H17&I17&J17&F17 -> FFDRSTRUOTH | BD17: =D17&E17&N17&O17&P17&Q17&F17 -> NULLNULLNULLNULL | BE17: =D17&E17&U17&V17&W17&X17&F17 -> NULLNULLNULLNULL | BF17: =D17&E17&AB17&AC17&AD17&AE17&F17 -> NULLNULLNULLNULL | BG17: =D17&E17&AI17&AJ17&AK17&AL17&F17 -> NULLNULLNULLNULL | BH17: =IF(COUNTIF($BB:$BF,BC17)>1,"Duplicated","") -> Duplicated | BI17: =IF(COUNTIF($BB:$BF,BD17)>1,"Duplicated","") -> Duplicated | BJ17: =IF(COUNTIF($BB:$BF,BE17)>1,"Duplicated","") -> Duplicated | BK17: =IF(COUNTIF($BB:$BF,BF17)>1,"Duplicated","") -> Duplicated | BL17: =IF(COUNTIF($BB:$BF,BG17)>1,"Duplicated","") -> Duplicated | BM17: HR door
G18: FF | H18: DR | I18: STRU | J18: OTH | K18: NULL | L18: NULL | M18: Lift Door | N18: NULL | O18: NULL | P18: NULL | Q18: NULL | R18: NULL | S18: NULL | T18: NULL | U18: NULL | V18: NULL | W18: NULL | X18: NULL | Y18: NULL | Z18: NULL | AA18: NULL | AB18: NULL | AC18: NULL | AD18: NULL | AE18: NULL | AF18: NULL | AG18: NULL | AH18: NULL | AI18: NULL | AJ18: NULL | AK18: NULL | AL18: NULL | AM18: NULL | AN18: NULL | AO18: NULL | AP18: NULL | AQ18: NULL | AR18: NULL | AS18: NULL | AT18: NULL | AU18: NULL | AV18: NULL | AW18: NULL | AX18: =IF(COUNTIF('ACTION Element Code Table'!$A:$A,G18&"_"&H18&"_"&I18&"_"&J18)=1,VLOOKUP(G18&"_"&H18&"_"&I18&"_"&J18,'ACTION Element Code Table'!$A:$C,3,FALSE),IF(G18&"_"&H18&"_"&I18&"_"&J18="NULL_NULL_NULL_NULL","NULL","Not exist in ACTION Element Code Table")) -> DOOR (SEE REMARKS) | AY18: =IF(COUNTIF('ACTION Element Code Table'!$A:$A,N18&"_"&O18&"_"&P18&"_"&Q18)=1,VLOOKUP(N18&"_"&O18&"_"&P18&"_"&Q18,'ACTION Element Code Table'!$A:$C,3,FALSE),IF(N18&"_"&O18&"_"&P18&"_"&Q18="NULL_NULL_NULL_NULL","NULL","Not exist in ACTION Element Code Table")) -> NULL | AZ18: =IF(COUNTIF('ACTION Element Code Table'!$A:$A,U18&"_"&V18&"_"&W18&"_"&X18)=1,VLOOKUP(U18&"_"&V18&"_"&W18&"_"&X18,'ACTION Element Code Table'!$A:$C,3,FALSE),IF(U18&"_"&V18&"_"&W18&"_"&X18="NULL_NULL_NULL_NULL","NULL","Not exist in ACTION Element Code Table")) -> NULL | BA18: =IF(COUNTIF('ACTION Element Code Table'!$A:$A,AB18&"_"&AC18&"_"&AD18&"_"&AE18)=1,VLOOKUP(AB18&"_"&AC18&"_"&AD18&"_"&AE18,'ACTION Element Code Table'!$A:$C,3,FALSE),IF(AB18&"_"&AC18&"_"&AD18&"_"&AE18="NULL_NULL_NULL_NULL","NULL","Not exist in ACTION Element Code Table")) -> NULL | BB18: =IF(COUNTIF('ACTION Element Code Table'!$A:$A,AI18&"_"&AJ18&"_"&AK18&"_"&AL18)=1,VLOOKUP(AI18&"_"&AJ18&"_"&AK18&"_"&AL18,'ACTION Element Code Table'!$A:$C,3,FALSE),IF(AI18&"_"&AJ18&"_"&AK18&"_"&AL18="NULL_NULL_NULL_NULL","NULL","Not exist in ACTION Element Code Table")) -> NULL | BC18: =D18&E18&G18&H18&I18&J18&F18 -> FFDRSTRUOTH | BD18: =D18&E18&N18&O18&P18&Q18&F18 -> NULLNULLNULLNULL | BE18: =D18&E18&U18&V18&W18&X18&F18 -> NULLNULLNULLNULL | BF18: =D18&E18&AB18&AC18&AD18&AE18&F18 -> NULLNULLNULLNULL | BG18: =D18&E18&AI18&AJ18&AK18&AL18&F18 -> NULLNULLNULLNULL | BH18: =IF(COUNTIF($BB:$BF,BC18)>1,"Duplicated","") -> Duplicated | BI18: =IF(COUNTIF($BB:$BF,BD18)>1,"Duplicated","") -> Duplicated | BJ18: =IF(COUNTIF($BB:$BF,BE18)>1,"Duplicated","") -> Duplicated | BK18: =IF(COUNTIF($BB:$BF,BF18)>1,"Duplicated","") -> Duplicated | BL18: =IF(COUNTIF($BB:$BF,BG18)>1,"Duplicated","") -> Duplicated | BM18: Lift Door
G19: FF | H19: FFOT | I19: NULL | J19: NULL | K19: NULL | L19: NULL | M19: NULL | N19: NULL | O19: NULL | P19: NULL | Q19: NULL | R19: NULL | S19: NULL | T19: NULL | U19: NULL | V19: NULL | W19: NULL | X19: NULL | Y19: NULL | Z19: NULL | AA19: NULL | AB19: NULL | AC19: NULL | AD19: NULL | AE19: NULL | AF19: NULL | AG19: NULL | AH19: NULL | AI19: NULL | AJ19: NULL | AK19: NULL | AL19: NULL | AM19: NULL | AN19: NULL | AO19: NULL | AP19: NULL | AQ19: NULL | AR19: NULL | AS19: NULL | AT19: NULL | AU19: NULL | AV19: NULL | AW19: NULL | AX19: =IF(COUNTIF('ACTION Element Code Table'!$A:$A,G19&"_"&H19&"_"&I19&"_"&J19)=1,VLOOKUP(G19&"_"&H19&"_"&I19&"_"&J19,'ACTION Element Code Table'!$A:$C,3,FALSE),IF(G19&"_"&H19&"_"&I19&"_"&J19="NULL_NULL_NULL_NULL","NULL","Not exist in ACTION Element Code Table")) -> OTHER FIXTURES & FITTING | AY19: =IF(COUNTIF('ACTION Element Code Table'!$A:$A,N19&"_"&O19&"_"&P19&"_"&Q19)=1,VLOOKUP(N19&"_"&O19&"_"&P19&"_"&Q19,'ACTION Element Code Table'!$A:$C,3,FALSE),IF(N19&"_"&O19&"_"&P19&"_"&Q19="NULL_NULL_NULL_NULL","NULL","Not exist in ACTION Element Code Table")) -> NULL | AZ19: =IF(COUNTIF('ACTION Element Code Table'!$A:$A,U19&"_"&V19&"_"&W19&"_"&X19)=1,VLOOKUP(U19&"_"&V19&"_"&W19&"_"&X19,'ACTION Element Code Table'!$A:$C,3,FALSE),IF(U19&"_"&V19&"_"&W19&"_"&X19="NULL_NULL_NULL_NULL","NULL","Not exist in ACTION Element Code Table")) -> NULL | BA19: =IF(COUNTIF('ACTION Element Code Table'!$A:$A,AB19&"_"&AC19&"_"&AD19&"_"&AE19)=1,VLOOKUP(AB19&"_"&AC19&"_"&AD19&"_"&AE19,'ACTION Element Code Table'!$A:$C,3,FALSE),IF(AB19&"_"&AC19&"_"&AD19&"_"&AE19="NULL_NULL_NULL_NULL","NULL","Not exist in ACTION Element Code Table")) -> NULL | BB19: =IF(COUNTIF('ACTION Element Code Table'!$A:$A,AI19&"_"&AJ19&"_"&AK19&"_"&AL19)=1,VLOOKUP(AI19&"_"&AJ19&"_"&AK19&"_"&AL19,'ACTION Element Code Table'!$A:$C,3,FALSE),IF(AI19&"_"&AJ19&"_"&AK19&"_"&AL19="NULL_NULL_NULL_NULL","NULL","Not exist in ACTION Element Code Table")) -> NULL | BC19: =D19&E19&G19&H19&I19&J19&F19 -> FFFFOTNULLNULL | BD19: =D19&E19&N19&O19&P19&Q19&F19 -> NULLNULLNULLNULL | BE19: =D19&E19&U19&V19&W19&X19&F19 -> NULLNULLNULLNULL | BF19: =D19&E19&AB19&AC19&AD19&AE19&F19 -> NULLNULLNULLNULL | BG19: =D19&E19&AI19&AJ19&AK19&AL19&F19 -> NULLNULLNULLNULL | BH19: =IF(COUNTIF($BB:$BF,BC19)>1,"Duplicated","") -> Duplicated | BI19: =IF(COUNTIF($BB:$BF,BD19)>1,"Duplicated","") -> Duplicated | BJ19: =IF(COUNTIF($BB:$BF,BE19)>1,"Duplicated","") -> Duplicated | BK19: =IF(COUNTIF($BB:$BF,BF19)>1,"Duplicated","") -> Duplicated | BL19: =IF(COUNTIF($BB:$BF,BG19)>1,"Duplicated","") -> Duplicated | BM19: Corner Guard | BN19: Fixture
G20: FF | H20: WIN | I20: POIN | J20: OTH | K20: NULL | L20: NULL | M20: Louvre | N20: NULL | O20: NULL | P20: NULL | Q20: NULL | R20: NULL | S20: NULL | T20: NULL | U20: NULL | V20: NULL | W20: NULL | X20: NULL | Y20: NULL | Z20: NULL | AA20: NULL | AB20: NULL | AC20: NULL | AD20: NULL | AE20: NULL | AF20: NULL | AG20: NULL | AH20: NULL | AI20: NULL | AJ20: NULL | AK20: NULL | AL20: NULL | AM20: NULL | AN20: NULL | AO20: NULL | AP20: NULL | AQ20: NULL | AR20: NULL | AS20: NULL | AT20: NULL | AU20: NULL | AV20: NULL | AW20: NULL | AX20: =IF(COUNTIF('ACTION Element Code Table'!$A:$A,G20&"_"&H20&"_"&I20&"_"&J20)=1,VLOOKUP(G20&"_"&H20&"_"&I20&"_"&J20,'ACTION Element Code Table'!$A:$C,3,FALSE),IF(G20&"_"&H20&"_"&I20&"_"&J20="NULL_NULL_NULL_NULL","NULL","Not exist in ACTION Element Code Table")) -> POINTING OF WINDOW (SEE REMARK) | AY20: =IF(COUNTIF('ACTION Element Code Table'!$A:$A,N20&"_"&O20&"_"&P20&"_"&Q20)=1,VLOOKUP(N20&"_"&O20&"_"&P20&"_"&Q20,'ACTION Element Code Table'!$A:$C,3,FALSE),IF(N20&"_"&O20&"_"&P20&"_"&Q20="NULL_NULL_NULL_NULL","NULL","Not exist in ACTION Element Code Table")) -> NULL | AZ20: =IF(COUNTIF('ACTION Element Code Table'!$A:$A,U20&"_"&V20&"_"&W20&"_"&X20)=1,VLOOKUP(U20&"_"&V20&"_"&W20&"_"&X20,'ACTION Element Code Table'!$A:$C,3,FALSE),IF(U20&"_"&V20&"_"&W20&"_"&X20="NULL_NULL_NULL_NULL","NULL","Not exist in ACTION Element Code Table")) -> NULL | BA20: =IF(COUNTIF('ACTION Element Code Table'!$A:$A,AB20&"_"&AC20&"_"&AD20&"_"&AE20)=1,VLOOKUP(AB20&"_"&AC20&"_"&AD20&"_"&AE20,'ACTION Element Code Table'!$A:$C,3,FALSE),IF(AB20&"_"&AC20&"_"&AD20&"_"&AE20="NULL_NULL_NULL_NULL","NULL","Not exist in ACTION Element Code Table")) -> NULL | BB20: =IF(COUNTIF('ACTION Element Code Table'!$A:$A,AI20&"_"&AJ20&"_"&AK20&"_"&AL20)=1,VLOOKUP(AI20&"_"&AJ20&"_"&AK20&"_"&AL20,'ACTION Element Code Table'!$A:$C,3,FALSE),IF(AI20&"_"&AJ20&"_"&AK20&"_"&AL20="NULL_NULL_NULL_NULL","NULL","Not exist in ACTION Element Code Table")) -> NULL | BC20: =D20&E20&G20&H20&I20&J20&F20 -> FFWINPOINOTH | BD20: =D20&E20&N20&O20&P20&Q20&F20 -> NULLNULLNULLNULL | BE20: =D20&E20&U20&V20&W20&X20&F20 -> NULLNULLNULLNULL | BF20: =D20&E20&AB20&AC20&AD20&AE20&F20 -> NULLNULLNULLNULL | BG20: =D20&E20&AI20&AJ20&AK20&AL20&F20 -> NULLNULLNULLNULL | BH20: =IF(COUNTIF($BB:$BF,BC20)>1,"Duplicated","") | BI20: =IF(COUNTIF($BB:$BF,BD20)>1,"Duplicated","") -> Duplicated | BJ20: =IF(COUNTIF($BB:$BF,BE20)>1,"Duplicated","") -> Duplicated | BK20: =IF(COUNTIF($BB:$BF,BF20)>1,"Duplicated","") -> Duplicated | BL20: =IF(COUNTIF($BB:$BF,BG20)>1,"Duplicated","") -> Duplicated | BM20: Louvre
